Workbook

Sheet голые
A1: Розничный прайс-лист на продукцию ООО "Дымоход - Трейд плюс " от 01.04.2024
A3: Труба без изоляции — ОЦИНКОВКА
B4: Ø 100 | C4: Ø 110 | D4: Ø 120 | E4: Ø 130 | F4: Ø 140 | G4: Ø 150 | H4: Ø 160 | I4: Ø 180 | J4: Ø 200 | K4: Ø 210 | L4: Ø 220 | M4: Ø 230 | N4: Ø 250 | O4: Ø 280 | P4: Ø 300
A5: ТрубаL=1000 мм | B5: 737 | C5: 782.1 | D5: 845.9 | E5: 885.5 | F5: 937.2 | G5: 1009.8 | H5: 1080.2 | I5: 1186.9 | J5: 1336.5 | K5: 1426.7 | L5: 1482.8 | M5: 1554.3 | N5: 1645.6 | O5: 1910.7 | P5: 2085.6
A6: Труба L=750 мм | B6: 599.5 | C6: 634.7 | D6: 711.7 | E6: 750.2 | F6: 805.2 | G6: 847 | H6: 895.4 | I6: 1067 | J6: 1155 | K6: 1232 | L6: 1293.6 | M6: 1379.4 | N6: 1482.8 | O6: 1558.7 | P6: 1732.5
A7: Труба L=500 мм | B7: 463.1 | C7: 517 | D7: 563.2 | E7: 599.5 | F7: 691.9 | G7: 731.5 | H7: 782.1 | I7: 847 | J7: 924 | K7: 1001 | L7: 1039.5 | M7: 1078 | N7: 1162.7 | O7: 1309 | P7: 1424.5
A8: Труба L=350 мм | B8: 391.6 | C8: 427.9 | D8: 492.8 | E8: 531.3 | F8: 597.3 | G8: 640.2 | H8: 684.2 | I8: 748 | J8: 892.1 | K8: 902 | L8: 935 | M8: 965.8 | N8: 1100 | O8: 1202.3 | P8: 1391.5
A9: Труба L=250 мм | B9: 383.9 | C9: 402.6 | D9: 430.1 | E9: 447.7 | F9: 468.6 | G9: 500.5 | H9: 532.4 | I9: 578.6 | J9: 691.9 | K9: 697.4 | L9: 721.6 | M9: 745.8 | N9: 848.1 | O9: 922.9 | P9: 1068.1
A10: Труба L=150 мм | B10: 266.2 | C10: 276.1 | D10: 293.7 | E10: 303.6 | F10: 316.8 | G10: 335.5 | H10: 355.3 | I10: 383.9 | J10: 463.1 | K10: 467.5 | L10: 481.8 | M10: 496.1 | N10: 570.9 | O10: 614.9 | P10: 715
A11: Отвод 90 гр | B11: 790.9 | C11: 885.5 | D11: 907.5 | E11: 975.7 | F11: 1006.5 | G11: 1079.1 | H11: 1201.2 | I11: 1249.6 | J11: 1417.9 | K11: 1499.3 | L11: 1564.2 | M11: 1639 | N11: 1793 | O11: 1994.3 | P11: 2179.1
A12: Отвод 45 гр | B12: 653.4 | C12: 735.9 | D12: 808.5 | E12: 872.3 | F12: 968 | G12: 1040.6 | H12: 1162.7 | I12: 1211.1 | J12: 1379.4 | K12: 1460.8 | L12: 1525.7 | M12: 1600.5 | N12: 1754.5 | O12: 1955.8 | P12: 2140.6
A13: Зонт | B13: 653.4 | C13: 693 | D13: 708.4 | E13: 772.2 | F13: 776.6 | G13: 809.6 | H13: 899.8 | I13: 1071.4 | J13: 1103.3 | K13: 1179.2 | L13: 1287 | M13: 1423.4 | N13: 1699.5 | O13: 1841.4 | P13: 1926.1
A14: Тройник с К/О 90гр | B14: 1408 | C14: 1450.9 | D14: 1502.6 | E14: 1555.4 | F14: 1611.5 | G14: 1669.8 | H14: 1685.2 | I14: 1813.9 | J14: 1918.4 | K14: 1989.9 | L14: 2062.5 | M14: 2139.5 | N14: 2411.2 | O14: 2678.5 | P14: 3001.9
A15: Тройник с К/О 45гр | B15: 1593.9 | C15: 1549.9 | D15: 1620.3 | E15: 1694 | F15: 1772.1 | G15: 1853.5 | H15: 2014.1 | I15: 2202.2 | J15: 2525.6 | K15: 2637.8 | L15: 2812.7 | M15: 2942.5 | N15: 3358.3 | O15: 3815.9 | P15: 4315.3
A16: Четверник с к/о 90гр | B16: 2077.9 | C16: 2026.2 | D16: 2121.9 | E16: 2223.1 | F16: 2329.8 | G16: 2446.4 | H16: 2671.9 | I16: 2953.5 | J16: 3406.7 | K16: 3573.9 | L16: 3748.8 | M16: 3929.2 | N16: 4490.2 | O16: 5129.3 | P16: 5810.2
... A22: Хомут широкий | B22: 479.6 | C22: 489.5 | D22: 499.4 | E22: 508.2 | F22: 518.1 | G22: 529.1 | H22: 558.8 | I22: 581.9 | J22: 596.2 | K22: 607.2 | L22: 609.4 | M22: 624.8 | N22: 676.5 | O22: 712.8 | P22: 789.8
A24: Розничный прайс-лист на продукцию ООО "Дымоход - Трейд плюс " от 20.01.2025
A26: Труба без изоляции — Нержавеющая сталь AISI 430 (толщина 0,5 мм)
B27: Ø 100 | C27: Ø 110 | D27: Ø 120 | E27: Ø 130 | F27: Ø 140 | G27: Ø 150 | H27: Ø 160 | I27: Ø 180 | J27: Ø 200 | K27: Ø 210 | L27: Ø 220 | M27: Ø 230 | N27: Ø 250 | O27: Ø 280 | P27: Ø 300
A28: ТрубаL=1000 мм | B28: 968.99 | C28: 1028.445 | D28: 1111.935 | E28: 1163.8 | F28: 1232.11 | G28: 1328.25 | H28: 1419.33 | I28: 1561.01 | J28: 1757.085 | K28: 1874.73 | L28: 1948.1 | M28: 2041.71 | N28: 2163.15 | O28: 2511.025 | P28: 2741.255
A29: Труба L=750 мм | B29: 788.095 | C29: 833.635 | D29: 934.835 | E29: 985.435 | F29: 1057.54 | G29: 1113.2 | H29: 1176.45 | I29: 1401.62 | J29: 1518 | K29: 1619.2 | L29: 1700.16 | M29: 1812.745 | N29: 1948.1 | O29: 2048.035 | P29: 2277
A30: Труба L=500 мм | B30: 608.465 | C30: 680.57 | D30: 741.29 | E30: 788.095 | F30: 909.535 | G30: 961.4 | H30: 1027.18 | I30: 1113.2 | J30: 1214.4 | K30: 1315.6 | L30: 1366.2 | M30: 1416.8 | N30: 1528.12 | O30: 1720.4 | P30: 1872.2
A31: Труба L=350 мм | B31: 514.855 | C31: 561.66 | D31: 647.68 | E31: 698.28 | F31: 784.3 | G31: 842.49 | H31: 898.15 | I31: 982.905 | J31: 1172.655 | K31: 1185.305 | L31: 1228.315 | M31: 1268.795 | N31: 1444.63 | O31: 1579.985 | P31: 1829.19
A32: Труба L=250 мм | B32: 503.47 | C32: 528.77 | D32: 565.455 | E32: 588.225 | F32: 616.055 | G32: 657.8 | H32: 700.81 | I32: 760.265 | J32: 908.27 | K32: 917.125 | L32: 948.75 | M32: 979.11 | N32: 1115.73 | O32: 1211.87 | P32: 1404.15
A33: Труба L=150 мм | B33: 349.14 | C33: 363.055 | D33: 385.825 | E33: 398.475 | F33: 416.185 | G33: 440.22 | H33: 468.05 | I33: 503.47 | J33: 609.73 | K33: 614.79 | L33: 632.5 | M33: 651.475 | N33: 750.145 | O33: 807.07 | P33: 939.895
A34: Отвод 90 гр | B34: 966.46 | C34: 1018.325 | D34: 1113.2 | E34: 1196.69 | F34: 1323.19 | G34: 1418.065 | H34: 1578.72 | I34: 1641.97 | J34: 1864.61 | K34: 1970.87 | L34: 2056.89 | M34: 2153.03 | N34: 2355.43 | O34: 2621.08 | P34: 2863.96
A35: Отвод 45 гр | B35: 858.935 | C35: 967.725 | D35: 1062.6 | E35: 1146.09 | F35: 1272.59 | G35: 1367.465 | H35: 1528.12 | I35: 1591.37 | J35: 1814.01 | K35: 1920.27 | L35: 2006.29 | M35: 2102.43 | N35: 2304.83 | O35: 2570.48 | P35: 2813.36
A36: Зонт | B36: 751.41 | C36: 7972.03 | D36: 869.055 | E36: 947.485 | F36: 1020.855 | G36: 1065.13 | H36: 1181.51 | I36: 1409.21 | J36: 1449.69 | K36: 1549.625 | L36: 1692.57 | M36: 1870.935 | N36: 2233.99 | O36: 2419.945 | P36: 2531.265
A37: Дефлектор | B37: 1128.38 | C37: 1200.485 | D37: 1246.025 | E37: 1404.15 | F37: 1482.58 | G37: 1640.705 | H37: 1746.965 | I37: 2006.29 | J37: 2340.25 | K37: 2531.265 | L37: 2853.84 | M37: 2996.785 | N37: 3549.59 | O37: 3912.645 | P37: 4098.6
A38: Тройник с К/О 90гр | B38: 1720.4 | C38: 1773.53 | D38: 1835.515 | E38: 1900.03 | F38: 1968.34 | G38: 2040.445 | H38: 2067.01 | I38: 2223.87 | J38: 2522.41 | K38: 2614.755 | L38: 2710.895 | M38: 2810.83 | N38: 3168.825 | O38: 3520.495 | P38: 3944.27
A39: Тройник с К/О 45гр | B39: 1955.69 | C39: 2036.65 | D39: 2128.995 | E39: 2226.4 | F39: 2328.865 | G39: 2436.39 | H39: 2646.38 | I39: 2894.32 | J39: 3319.36 | K39: 3467.365 | L39: 3696.33 | M39: 3868.37 | N39: 4413.585 | O39: 5015.725 | P39: 56270.995
... A46: Хомут широкий | B46: 629.97 | C46: 642.62 | D46: 656.535 | E46: 667.92 | F46: 680.57 | G46: 695.75 | H46: 734.965 | I46: 765.325 | J46: 783.035 | K46: 798.215 | L46: 800.745 | M46: 820.985 | N46: 889.295 | O46: 936.1 | P46: 1038.565
A48: Розничный прайс-лист на продукцию ООО "Дымоход - Трейд плюс " от 20.01.2025
A50: Труба без изоляции — Нержавеющая сталь AISI 430 (толщина 0,8 мм)
B51: Ø 100 | C51: Ø 110 | D51: Ø 120 | E51: Ø 130 | F51: Ø 140 | G51: Ø 150 | H51: Ø 160 | I51: Ø 180 | J51: Ø 200 | K51: Ø 210 | L51: Ø 220 | M51: Ø 230 | N51: Ø 250 | O51: Ø 280 | P51: Ø 300
A52: ТрубаL=1000 мм | B52: 1342.165 | C52: 1520.53 | D52: 1593.9 | E52: 1735.58 | F52: 1843.105 | G52: 1994.905 | H52: 2136.585 | I52: 2360.49 | J52: 2646.38 | K52: 2676.74 | L52: 2785.53 | M52: 2894.32 | N52: 3261.17 | O52: 3598.925 | P52: 4151.73
A53: Труба L=750 мм | B53: 1209.34 | C53: 1295.36 | D53: 1414.27 | E53: 1488.905 | F53: 1586.31 | G53: 1722.93 | H53: 1850.695 | I53: 2051.83 | J53: 2452.835 | K53: 2481.93 | L53: 2586.925 | M53: 2690.655 | N53: 3046.12 | O53: 3368.695 | P53: 3902.525
A54: Труба L=500 мм | B54: 1008.205 | C54: 1076.515 | D54: 1294.095 | E54: 1362.405 | F54: 1449.69 | G54: 1572.395 | H54: 1690.04 | I54: 1870.935 | J54: 2173.27 | K54: 2264.35 | L54: 2359.225 | M54: 2452.835 | N54: 2777.94 | O54: 3070.155 | P54: 3557.18
A55: Труба L=350 мм | B55: 898.15 | C55: 952.545 | D55: 1027.18 | E55: 1073.985 | F55: 1135.97 | G55: 1221.99 | H55: 1305.48 | I55: 1433.245 | J55: 1601.49 | K55: 1721.665 | L55: 1787.445 | M55: 1853.225 | N55: 2094.84 | O55: 2299.77 | P55: 2653.97
A56: Труба L=250 мм | B56: 712.195 | C56: 751.41 | D56: 804.54 | E56: 837.43 | F56: 881.705 | G56: 943.69 | H56: 1006.94 | I56: 1096.755 | J56: 1302.95 | K56: 1316.865 | L56: 1363.67 | M56: 1410.475 | N56: 1597.695 | O56: 1744.435 | P56: 2013.88
...

Sheet 50 изоляция
A1: Розничный прайс-лист на продукцию ООО "Дымоход - Трейд плюс " от 20.01.2025
K2: 50мм
A4: Внутренняя труба — ОЦИНКОВКА
A5: Наружный кожух — ОЦИНКОВКА
A6: Изоляция — Rockwool Wired Mat 105 (толщина 50мм)
B7: Ø 100/200 | C7: Ø 110/210 | D7: Ø 120/220 | E7: Ø 130/230 | F7: Ø 140/240 | G7: Ø 150/250 | H7: Ø 160/260 | I7: Ø 180/280 | J7: Ø 200/300 | K7: Ø 250/350 | L7: Ø 280/380 | M7: Ø 300/400
A8: Труба L=1000мм | B8: 1996.5 | C8: 2100.56 | D8: 2305.05 | E8: 2398.22 | F8: 2631.75 | G8: 2816.88 | H8: 2994.75 | I8: 3222.23 | J8: 3643.31 | K8: 4276.14 | L8: 4656.08 | M8: 4910.18
A9: Труба L=750 мм | B9: 1703.68 | C9: 1815 | D9: 1948.1 | E9: 2107.82 | F9: 2251.81 | G9: 2365.55 | H9: 2429.68 | I9: 2594.24 | J9: 2914.89 | K9: 3395.26 | L9: 3683.24 | M9: 3875.63
A10: Труба L=500 мм | B10: 1396.34 | C10: 1490.72 | D10: 1588.73 | E10: 1726.67 | F10: 1822.26 | G10: 1995.29 | H10: 2038.85 | I10: 2147.75 | J10: 2369.18 | K10: 2694.67 | L10: 2889.48 | M10: 3020.16
A11: Труба L=350 мм | B11: 1157.97 | C11: 1277.76 | D11: 1347.94 | E11: 1392.71 | F11: 1522.18 | G11: 1595.99 | H11: 1628.66 | I11: 1748.45 | J11: 1911.8 | K11: 2340.14 | L11: 2543.42 | M11: 2665.63
A12: Труба L=250 мм | B12: 993.41 | C12: 1035.76 | D12: 1082.95 | E12: 1114.41 | F12: 1205.16 | G12: 1353.99 | H12: 1375.77 | I12: 1458.05 | J12: 1639.55 | K12: 1886.39 | L12: 2035.22 | M12: 2123.55
A13: Труба L=150 мм | B13: 832.48 | C13: 879.67 | D13: 907.5 | E13: 928.07 | F13: 982.52 | G13: 1023.66 | H13: 1036.97 | I13: 1087.79 | J13: 1203.95 | K13: 1353.99 | L13: 1444.74 | M13: 1497.98
A14: Отвод 90 гр | B14: 2296.58 | C14: 2429.68 | D14: 2563.99 | E14: 2706.77 | F14: 2752.75 | G14: 2888.27 | H14: 3131.48 | I14: 3494.48 | J14: 4115.21 | K14: 5043.28 | L14: 5599.88 | M14: 5970.14
A15: Отвод 45 гр | B15: 2115.08 | C15: 2248.18 | D15: 2382.49 | E15: 2525.27 | F15: 2571.25 | G15: 2706.77 | H15: 2949.98 | I15: 3312.98 | J15: 3933.71 | K15: 4861.78 | L15: 5418.38 | M15: 5788.64
A16: Тройник с К/О 90гр | B16: 3495.69 | C16: 3632.42 | D16: 3840.54 | E16: 3959.12 | F16: 4126.1 | G16: 4411.66 | H16: 4668.18 | I16: 5210.26 | J16: 5567.21 | K16: 6874.01 | L16: 7658.09 | M16: 8180.81
A17: Тройник с К/О 45гр | B17: 4245.89 | C17: 4363.26 | D17: 4550.81 | E17: 4964.63 | F17: 5120.72 | G17: 5682.16 | H17: 6148.01 | I17: 6688.88 | J17: 7808.13 | K17: 9146.39 | L17: 9949.83 | M17: 10431.41
A18: Четверник с К/О 90гр | B18: 7885.57 | C18: 8131.2 | D18: 8338.11 | E18: 8569.22 | F18: 8830.58 | G18: 9422.27 | H18: 9736.87 | I18: 10413.26 | J18: 11678.92 | K18: 13771.01 | L18: 15026.99 | M18: 9256.5
A19: Заглушка опорная | B19: 955.9 | C19: 975.26 | D19: 1045.44 | E19: 1159.18 | F19: 1245.09 | G19: 1320.11 | H19: 1433.85 | I19: 1481.04 | J19: 1655.28 | K19: 1894.86 | L19: 2037.64 | M19: 2122.34
... A22: Зонт-конус | B22: 1415.7 | C22: 1464.1 | D22: 1635.92 | E22: 1677.06 | F22: 1790.8 | G22: 2064.26 | H22: 2167.11 | I22: 2380.07 | J22: 2551.89 | K22: 3106.07 | L22: 3438.82 | M22: 3638.47
A24: Розничный прайс-лист на продукцию ООО "Дымоход - Трейд плюс " от 20.01.2025
K25: 50мм
A27: Внутренняя труба — ОЦИНКОВКА
A28: Наружный кожух — Нержавеющая сталь AISI 430 (толщина 0,5мм)
A29: Изоляция — Rockwool Wired Mat 105 (толщина 50мм)
B30: Ø 100/200 | C30: Ø 110/210 | D30: Ø 120/220 | E30: Ø 130/230 | F30: Ø 140/240 | G30: Ø 150/250 | H30: Ø 160/260 | I30: Ø 180/280 | J30: Ø 200/300 | K30: Ø 250/350 | L30: Ø 280/380 | M30: Ø 300/400
A31: Труба L=1000мм | B31: 2614.755 | C31: 2659.03 | D31: 2848.78 | E31: 3080.275 | F31: 3320.625 | G31: 3463.57 | H31: 3631.815 | I31: 3984.75 | J31: 4364.25 | K31: 5313 | L31: 5882.25 | M31: 6261.75
A32: Труба L=750 мм | B32: 2142.91 | C32: 2306.095 | D32: 2503.435 | E32: 2678.005 | F32: 2837.395 | G32: 2974.015 | H32: 3143.525 | I32: 3591.335 | J32: 3696.33 | K32: 4554 | L32: 4952.475 | M32: 5240.895
A33: Труба L=500 мм | B33: 1669.8 | C33: 1810.215 | D33: 1973.4 | E33: 2121.405 | F33: 2322.54 | G33: 2466.75 | H33: 2564.155 | I33: 2785.53 | J33: 3036 | K33: 3700.125 | L33: 4098.6 | M33: 4364.25
A34: Труба L=350 мм | B34: 1386.44 | C34: 1512.94 | D34: 1654.62 | E34: 1787.445 | F34: 1926.595 | G34: 1992.375 | H34: 2094.84 | I34: 2244.11 | J34: 2466.75 | K34: 2971.485 | L34: 3273.82 | M34: 3476.22
A35: Труба L=250 мм | B35: 1315.6 | C35: 1330.78 | D35: 1387.705 | E35: 1429.45 | F35: 1535.71 | G35: 1610.345 | H35: 1641.97 | I35: 1748.23 | J35: 1979.725 | K35: 2279.53 | L35: 2457.895 | M35: 2578.07
A36: Труба L=150 мм | B36: 1003.145 | C36: 1012 | D36: 1046.155 | E36: 1070.19 | F36: 1132.175 | G36: 1184.04 | H36: 1203.015 | I36: 1349.755 | J36: 1495.23 | K36: 1679.92 | L36: 1789.975 | M36: 1863.345
A37: Отвод 90 гр | B37: 2958.835 | C37: 3199.185 | D37: 3345.925 | E37: 3692.535 | F37: 3934.15 | G37: 4182.09 | H37: 4419.91 | I37: 4956.27 | J37: 5505.28 | K37: 6903.105 | L37: 7608.975 | M37: 7972.03
A38: Отвод 45 гр | B38: 2769.085 | C38: 3009.435 | D38: 3156.175 | E38: 3502.785 | F38: 3676.09 | G38: 3992.34 | H38: 4230.16 | I38: 4766.52 | J38: 5315.53 | K38: 6713.355 | L38: 7419.225 | M38: 7782.28
A39: Тройник с К/О 90гр | B39: 3784.88 | C39: 4040.41 | D39: 4369.31 | E39: 4609.66 | F39: 4666.585 | G39: 4981.57 | H39: 5261.135 | I39: 5884.78 | J39: 6355.36 | K39: 7805.05 | L39: 8674.105 | M39: 9254.74
A40: Тройник с К/О 45гр | B40: 4796.88 | C40: 5042.29 | D40: 5268.725 | E40: 5644.43 | F40: 5939.175 | G40: 6586.855 | H40: 7302.845 | I40: 8044.135 | J40: 9224.38 | K40: 10894.18 | L40: 11896.06 | M40: 12498.2
A41: Четверник с К/О 90гр | B41: 8677.9 | C41: 8970.115 | D41: 9220.585 | E41: 9497.62 | F41: 9807.545 | G41: 10489.38 | H41: 10857.495 | I41: 11650.65 | J41: 13095.28 | K41: 15577.21 | L41: 17067.38 | M41: 18103.415
A42: Заглушка опорная | B42: 1110.67 | C42: 1133.44 | D42: 1214.4 | E42: 1345.96 | F42: 1445.895 | G42: 1534.445 | H42: 1666.005 | I42: 1720.4 | J42: 1922.8 | K42: 2199.835 | L42: 2365.55 | M42: 2466.75
... A46: Дефлектор-конус | B46: 2099.9 | C46: 2155.56 | D46: 2330.13 | E46: 2530 | F46: 2681.8 | G46: 2876.61 | H46: 3079.01 | I46: 3388.935 | J46: 3734.28 | K46: 3997.4 | L46: 4034.085 | M46: 4163
A48: Розничный прайс-лист на продукцию ООО "Дымоход - Трейд плюс " от 20.01.2025
K49: 50мм
...

Sheet 30 изоляция
A1: Розничный прайс-лист на продукцию ООО "Дымоход - Трейд плюс " от 20.01.2025
K2: 30мм
A4: Внутренняя труба — ОЦИНКОВКА
A5: Наружный кожух — ОЦИНКОВКА
A6: Изоляция — Rockwool Wired Mat 105 (толщина 30мм)
B7: Ø 100/160 | C7: Ø 110/170 | D7: Ø 120/180 | E7: Ø 130/190 | F7: Ø 140/200 | G7: Ø 150/210 | H7: Ø 160/220 | I7: Ø 180/240 | J7: Ø 200/260 | K7: Ø 250/310 | L7: Ø 280/340 | M7: Ø 300/360
A8: Труба L=1000мм | B8: ='50 изоляция'!B8*0.9 -> 1796.85 | C8: ='50 изоляция'!C8*0.9 -> 1890.504 | D8: ='50 изоляция'!D8*0.9 -> 2074.545 | E8: ='50 изоляция'!E8*0.9 -> 2158.398 | F8: ='50 изоляция'!F8*0.9 -> 2368.575 | G8: ='50 изоляция'!G8*0.9 -> 2535.192 | H8: ='50 изоляция'!H8*0.9 -> 2695.275 | I8: ='50 изоляция'!I8*0.9 -> 2900.007 | ... M8: ='50 изоляция'!M8*0.9 -> 4419.162
A9: Труба L=750 мм | B9: ='50 изоляция'!B9*0.9 -> 1533.312 | C9: ='50 изоляция'!C9*0.9 -> 1633.5 | D9: ='50 изоляция'!D9*0.9 -> 1753.29 | E9: ='50 изоляция'!E9*0.9 -> 1897.038 | F9: ='50 изоляция'!F9*0.9 -> 2026.629 | G9: ='50 изоляция'!G9*0.9 -> 2128.995 | H9: ='50 изоляция'!H9*0.9 -> 2186.712 | I9: ='50 изоляция'!I9*0.9 -> 2334.816 | ... M9: ='50 изоляция'!M9*0.9 -> 3488.067
A10: Труба L=500 мм | B10: ='50 изоляция'!B10*0.9 -> 1256.706 | C10: ='50 изоляция'!C10*0.9 -> 1341.648 | D10: ='50 изоляция'!D10*0.9 -> 1429.857 | E10: ='50 изоляция'!E10*0.9 -> 1554.003 | F10: ='50 изоляция'!F10*0.9 -> 1640.034 | G10: ='50 изоляция'!G10*0.9 -> 1795.761 | H10: ='50 изоляция'!H10*0.9 -> 1834.965 | I10: ='50 изоляция'!I10*0.9 -> 1932.975 | ... M10: ='50 изоляция'!M10*0.9 -> 2718.144
A11: Труба L=350 мм | B11: ='50 изоляция'!B11*0.9 -> 1042.173 | C11: ='50 изоляция'!C11*0.9 -> 1149.984 | D11: ='50 изоляция'!D11*0.9 -> 1213.146 | E11: ='50 изоляция'!E11*0.9 -> 1253.439 | F11: ='50 изоляция'!F11*0.9 -> 1369.962 | G11: ='50 изоляция'!G11*0.9 -> 1436.391 | H11: ='50 изоляция'!H11*0.9 -> 1465.794 | I11: ='50 изоляция'!I11*0.9 -> 1573.605 | ... M11: ='50 изоляция'!M11*0.9 -> 2399.067
A12: Труба L=250 мм | B12: ='50 изоляция'!B12*0.9 -> 894.069 | C12: ='50 изоляция'!C12*0.9 -> 932.184 | D12: ='50 изоляция'!D12*0.9 -> 974.655 | E12: ='50 изоляция'!E12*0.9 -> 1002.969 | F12: ='50 изоляция'!F12*0.9 -> 1084.644 | G12: ='50 изоляция'!G12*0.9 -> 1218.591 | H12: ='50 изоляция'!H12*0.9 -> 1238.193 | I12: ='50 изоляция'!I12*0.9 -> 1312.245 | ... M12: ='50 изоляция'!M12*0.9 -> 1911.195
A13: Труба L=150 мм | B13: ='50 изоляция'!B13*0.9 -> 749.232 | C13: ='50 изоляция'!C13*0.9 -> 791.703 | D13: ='50 изоляция'!D13*0.9 -> 816.75 | E13: ='50 изоляция'!E13*0.9 -> 835.263 | F13: ='50 изоляция'!F13*0.9 -> 884.268 | G13: ='50 изоляция'!G13*0.9 -> 921.294 | H13: ='50 изоляция'!H13*0.9 -> 933.273 | I13: ='50 изоляция'!I13*0.9 -> 979.011 | ... M13: ='50 изоляция'!M13*0.9 -> 1348.182
A14: Отвод 90 гр | B14: ='50 изоляция'!B14*0.9 -> 2066.922 | C14: ='50 изоляция'!C14*0.9 -> 2186.712 | D14: ='50 изоляция'!D14*0.9 -> 2307.591 | E14: ='50 изоляция'!E14*0.9 -> 2436.093 | F14: ='50 изоляция'!F14*0.9 -> 2477.475 | G14: ='50 изоляция'!G14*0.9 -> 2599.443 | H14: ='50 изоляция'!H14*0.9 -> 2818.332 | I14: ='50 изоляция'!I14*0.9 -> 3145.032 | ... M14: ='50 изоляция'!M14*0.9 -> 5373.126
A15: Отвод 45 гр | B15: ='50 изоляция'!B15*0.9 -> 1903.572 | C15: ='50 изоляция'!C15*0.9 -> 2023.362 | D15: ='50 изоляция'!D15*0.9 -> 2144.241 | E15: ='50 изоляция'!E15*0.9 -> 2272.743 | F15: ='50 изоляция'!F15*0.9 -> 2314.125 | G15: ='50 изоляция'!G15*0.9 -> 2436.093 | H15: ='50 изоляция'!H15*0.9 -> 2654.982 | I15: ='50 изоляция'!I15*0.9 -> 2981.682 | ... M15: ='50 изоляция'!M15*0.9 -> 5209.776
A16: Тройник с К/О 90гр | B16: ='50 изоляция'!B16*0.9 -> 3146.121 | C16: ='50 изоляция'!C16*0.9 -> 3269.178 | D16: ='50 изоляция'!D16*0.9 -> 3456.486 | E16: ='50 изоляция'!E16*0.9 -> 3563.208 | F16: ='50 изоляция'!F16*0.9 -> 3713.49 | G16: ='50 изоляция'!G16*0.9 -> 3970.494 | H16: ='50 изоляция'!H16*0.9 -> 4201.362 | I16: ='50 изоляция'!I16*0.9 -> 4689.234 | ... M16: ='50 изоляция'!M16*0.9 -> 7362.729
A17: Тройник с К/О 45гр | B17: ='50 изоляция'!B17*0.9 -> 3821.301 | C17: ='50 изоляция'!C17*0.9 -> 3926.934 | D17: ='50 изоляция'!D17*0.9 -> 4095.729 | E17: ='50 изоляция'!E17*0.9 -> 4468.167 | F17: ='50 изоляция'!F17*0.9 -> 4608.648 | G17: ='50 изоляция'!G17*0.9 -> 5113.944 | H17: ='50 изоляция'!H17*0.9 -> 5533.209 | I17: ='50 изоляция'!I17*0.9 -> 6019.992 | ... M17: ='50 изоляция'!M17*0.9 -> 9388.269
A18: Четверник с К/О 90гр | B18: ='50 изоляция'!B18*0.9 -> 7097.013 | C18: ='50 изоляция'!C18*0.9 -> 7318.08 | D18: ='50 изоляция'!D18*0.9 -> 7504.299 | E18: ='50 изоляция'!E18*0.9 -> 7712.298 | F18: ='50 изоляция'!F18*0.9 -> 7947.522 | G18: ='50 изоляция'!G18*0.9 -> 8480.043 | H18: ='50 изоляция'!H18*0.9 -> 8763.183 | I18: ='50 изоляция'!I18*0.9 -> 9371.934 | ... M18: ='50 изоляция'!M18*0.9 -> 8330.85
A19: Заглушка опорная | B19: ='50 изоляция'!B19*0.9 -> 860.31 | C19: ='50 изоляция'!C19*0.9 -> 877.734 | D19: ='50 изоляция'!D19*0.9 -> 940.896 | E19: ='50 изоляция'!E19*0.9 -> 1043.262 | F19: ='50 изоляция'!F19*0.9 -> 1120.581 | G19: ='50 изоляция'!G19*0.9 -> 1188.099 | H19: ='50 изоляция'!H19*0.9 -> 1290.465 | I19: ='50 изоляция'!I19*0.9 -> 1332.936 | ... M19: ='50 изоляция'!M19*0.9 -> 1910.106
... A22: Зонт-конус | B22: ='50 изоляция'!B22*0.9 -> 1274.13 | C22: ='50 изоляция'!C22*0.9 -> 1317.69 | D22: ='50 изоляция'!D22*0.9 -> 1472.328 | E22: ='50 изоляция'!E22*0.9 -> 1509.354 | F22: ='50 изоляция'!F22*0.9 -> 1611.72 | G22: ='50 изоляция'!G22*0.9 -> 1857.834 | H22: ='50 изоляция'!H22*0.9 -> 1950.399 | I22: ='50 изоляция'!I22*0.9 -> 2142.063 | ... M22: ='50 изоляция'!M22*0.9 -> 3274.623
A24: Розничный прайс-лист на продукцию ООО "Дымоход - Трейд плюс " от 20.01.2025
K25: 30мм
A27: Внутренняя труба — Оцинковка
A28: Наружный кожух — Нержавеющая сталь AISI 430 (толщина 0,5мм)
A29: Изоляция — Rockwool Wired Mat 105 (толщина 30мм)
B30: Ø 100/160 | C30: Ø 110/170 | D30: Ø 120/180 | E30: Ø 130/190 | F30: Ø 140/200 | G30: Ø 150/210 | H30: Ø 160/220 | I30: Ø 180/240 | J30: Ø 200/260 | K30: Ø 250/310 | L30: Ø 280/340 | M30: Ø 300/360
A31: Труба L=1000мм | B31: ='50 изоляция'!B31*0.9 -> 2353.2795 | C31: ='50 изоляция'!C31*0.9 -> 2393.127 | D31: ='50 изоляция'!D31*0.9 -> 2563.902 | E31: ='50 изоляция'!E31*0.9 -> 2772.2475 | F31: ='50 изоляция'!F31*0.9 -> 2988.5625 | G31: ='50 изоляция'!G31*0.9 -> 3117.213 | H31: ='50 изоляция'!H31*0.9 -> 3268.6335 | I31: ='50 изоляция'!I31*0.9 -> 3586.275 | ... M31: ='50 изоляция'!M31*0.9 -> 5635.575
A32: Труба L=750 мм | B32: ='50 изоляция'!B32*0.9 -> 1928.619 | C32: ='50 изоляция'!C32*0.9 -> 2075.4855 | D32: ='50 изоляция'!D32*0.9 -> 2253.0915 | E32: ='50 изоляция'!E32*0.9 -> 2410.2045 | F32: ='50 изоляция'!F32*0.9 -> 2553.6555 | G32: ='50 изоляция'!G32*0.9 -> 2676.6135 | H32: ='50 изоляция'!H32*0.9 -> 2829.1725 | I32: ='50 изоляция'!I32*0.9 -> 3232.2015 | ... M32: ='50 изоляция'!M32*0.9 -> 4716.8055
A33: Труба L=500 мм | B33: ='50 изоляция'!B33*0.9 -> 1502.82 | C33: ='50 изоляция'!C33*0.9 -> 1629.1935 | D33: ='50 изоляция'!D33*0.9 -> 1776.06 | E33: ='50 изоляция'!E33*0.9 -> 1909.2645 | F33: ='50 изоляция'!F33*0.9 -> 2090.286 | G33: ='50 изоляция'!G33*0.9 -> 2220.075 | H33: ='50 изоляция'!H33*0.9 -> 2307.7395 | I33: ='50 изоляция'!I33*0.9 -> 2506.977 | ... M33: ='50 изоляция'!M33*0.9 -> 3927.825
A34: Труба L=350 мм | B34: ='50 изоляция'!B34*0.9 -> 1247.796 | C34: ='50 изоляция'!C34*0.9 -> 1361.646 | D34: ='50 изоляция'!D34*0.9 -> 1489.158 | E34: ='50 изоляция'!E34*0.9 -> 1608.7005 | F34: ='50 изоляция'!F34*0.9 -> 1733.9355 | G34: ='50 изоляция'!G34*0.9 -> 1793.1375 | H34: ='50 изоляция'!H34*0.9 -> 1885.356 | I34: ='50 изоляция'!I34*0.9 -> 2019.699 | ... M34: ='50 изоляция'!M34*0.9 -> 3128.598
A35: Труба L=250 мм | B35: ='50 изоляция'!B35*0.9 -> 1184.04 | C35: ='50 изоляция'!C35*0.9 -> 1197.702 | D35: ='50 изоляция'!D35*0.9 -> 1248.9345 | E35: ='50 изоляция'!E35*0.9 -> 1286.505 | F35: ='50 изоляция'!F35*0.9 -> 1382.139 | G35: ='50 изоляция'!G35*0.9 -> 1449.3105 | H35: ='50 изоляция'!H35*0.9 -> 1477.773 | I35: ='50 изоляция'!I35*0.9 -> 1573.407 | ... M35: ='50 изоляция'!M35*0.9 -> 2320.263
A36: Труба L=150 мм | B36: ='50 изоляция'!B36*0.9 -> 902.8305 | C36: ='50 изоляция'!C36*0.9 -> 910.8 | D36: ='50 изоляция'!D36*0.9 -> 941.5395 | E36: ='50 изоляция'!E36*0.9 -> 963.171 | F36: ='50 изоляция'!F36*0.9 -> 1018.9575 | G36: ='50 изоляция'!G36*0.9 -> 1065.636 | H36: ='50 изоляция'!H36*0.9 -> 1082.7135 | I36: ='50 изоляция'!I36*0.9 -> 1214.7795 | ... M36: ='50 изоляция'!M36*0.9 -> 1677.0105
A37: Отвод 90 гр | B37: ='50 изоляция'!B37*0.9 -> 2662.9515 | C37: ='50 изоляция'!C37*0.9 -> 2879.2665 | D37: ='50 изоляция'!D37*0.9 -> 3011.3325 | E37: ='50 изоляция'!E37*0.9 -> 3323.2815 | F37: ='50 изоляция'!F37*0.9 -> 3540.735 | G37: ='50 изоляция'!G37*0.9 -> 3763.881 | H37: ='50 изоляция'!H37*0.9 -> 3977.919 | I37: ='50 изоляция'!I37*0.9 -> 4460.643 | ... M37: ='50 изоляция'!M37*0.9 -> 7174.827
A38: Отвод 45 гр | B38: ='50 изоляция'!B38*0.9 -> 2492.1765 | C38: ='50 изоляция'!C38*0.9 -> 2708.4915 | D38: ='50 изоляция'!D38*0.9 -> 2840.5575 | E38: ='50 изоляция'!E38*0.9 -> 3152.5065 | F38: ='50 изоляция'!F38*0.9 -> 3308.481 | G38: ='50 изоляция'!G38*0.9 -> 3593.106 | H38: ='50 изоляция'!H38*0.9 -> 3807.144 | I38: ='50 изоляция'!I38*0.9 -> 4289.868 | ... M38: ='50 изоляция'!M38*0.9 -> 7004.052
A39: Тройник с К/О 90гр | B39: ='50 изоляция'!B39*0.9 -> 3406.392 | C39: ='50 изоляция'!C39*0.9 -> 3636.369 | D39: ='50 изоляция'!D39*0.9 -> 3932.379 | E39: ='50 изоляция'!E39*0.9 -> 4148.694 | F39: ='50 изоляция'!F39*0.9 -> 4199.9265 | G39: ='50 изоляция'!G39*0.9 -> 4483.413 | H39: ='50 изоляция'!H39*0.9 -> 4735.0215 | I39: ='50 изоляция'!I39*0.9 -> 5296.302 | ... M39: ='50 изоляция'!M39*0.9 -> 8329.266
A40: Тройник с К/О 45гр | B40: ='50 изоляция'!B40*0.9 -> 4317.192 | C40: ='50 изоляция'!C40*0.9 -> 4538.061 | D40: ='50 изоляция'!D40*0.9 -> 4741.8525 | E40: ='50 изоляция'!E40*0.9 -> 5079.987 | F40: ='50 изоляция'!F40*0.9 -> 5345.2575 | G40: ='50 изоляция'!G40*0.9 -> 5928.1695 | H40: ='50 изоляция'!H40*0.9 -> 6572.5605 | I40: ='50 изоляция'!I40*0.9 -> 7239.7215 | ... M40: ='50 изоляция'!M40*0.9 -> 11248.38
A41: Четверник с К/О 90гр | B41: ='50 изоляция'!B41*0.9 -> 7810.11 | C41: ='50 изоляция'!C41*0.9 -> 8073.1035 | D41: ='50 изоляция'!D41*0.9 -> 8298.5265 | E41: ='50 изоляция'!E41*0.9 -> 8547.858 | F41: ='50 изоляция'!F41*0.9 -> 8826.7905 | G41: ='50 изоляция'!G41*0.9 -> 9440.442 | H41: ='50 изоляция'!H41*0.9 -> 9771.7455 | I41: ='50 изоляция'!I41*0.9 -> 10485.585 | ... M41: ='50 изоляция'!M41*0.9 -> 16293.074
A42: Заглушка опорная | B42: ='50 изоляция'!B42*0.9 -> 999.603 | C42: ='50 изоляция'!C42*0.9 -> 1020.096 | D42: ='50 изоляция'!D42*0.9 -> 1092.96 | E42: ='50 изоляция'!E42*0.9 -> 1211.364 | F42: ='50 изоляция'!F42*0.9 -> 1301.3055 | G42: ='50 изоляция'!G42*0.9 -> 1381.0005 | H42: ='50 изоляция'!H42*0.9 -> 1499.4045 | I42: ='50 изоляция'!I42*0.9 -> 1548.36 | ... M42: ='50 изоляция'!M42*0.9 -> 2220.075
... A46: Дефлектор-конус | B46: ='50 изоляция'!B46*0.9 -> 1889.91 | C46: ='50 изоляция'!C46*0.9 -> 1940.004 | D46: ='50 изоляция'!D46*0.9 -> 2097.117 | E46: ='50 изоляция'!E46*0.9 -> 2277 | F46: ='50 изоляция'!F46*0.9 -> 2413.62 | G46: ='50 изоляция'!G46*0.9 -> 2588.949 | H46: ='50 изоляция'!H46*0.9 -> 2771.109 | I46: ='50 изоляция'!I46*0.9 -> 3050.0415 | ... M46: ='50 изоляция'!M46*0.9 -> 3746.7
A48: Розничный прайс-лист на продукцию ООО "Дымоход - Трейд плюс " от 20.01.2025
K49: 30мм
...

Sheet 50 изол (каолин)
A1: Розничный прайс-лист на продукцию ООО "Дымоход - Трейд плюс " от 20.01.2025
K2: 50мм
A4: Внутренняя труба — ОЦИНКОВКА
A5: Наружный кожух — ОЦИНКОВКА
A6: Изоляция — Каолиновая вата (толщина 50мм)
B7: Ø 100/200 | C7: Ø 110/210 | D7: Ø 120/220 | E7: Ø 130/230 | F7: Ø 140/240 | G7: Ø 150/250 | H7: Ø 160/260 | I7: Ø 180/280 | J7: Ø 200/300 | K7: Ø 250/350 | L7: Ø 280/380 | M7: Ø 300/400
A8: Труба L=1000мм | B8: 2495.625 | C8: 2625.7 | D8: 2881.3125 | E8: 2997.775 | F8: 3289.6875 | G8: 3521.1 | H8: 3743.4375 | I8: 4027.7875 | J8: 4554.1375 | K8: 5345.175 | L8: 5820.1 | M8: 6137.725
A9: Труба L=750 мм | B9: 2129.6 | C9: 2268.75 | D9: 2435.125 | E9: 2634.775 | F9: 2814.7625 | G9: 2956.9375 | H9: 3037.1 | I9: 3242.8 | J9: 3643.6125 | K9: 4244.075 | L9: 4604.05 | M9: 4844.5375
A10: Труба L=500 мм | B10: 1745.425 | C10: 1863.4 | D10: 1985.9125 | E10: 2158.3375 | F10: 2277.825 | G10: 2494.1125 | H10: 2548.5625 | I10: 2684.6875 | J10: 2961.475 | K10: 3368.3375 | L10: 3611.85 | M10: 3775.2
A11: Труба L=350 мм | B11: 1447.4625 | C11: 1597.2 | D11: 1684.925 | E11: 1740.8875 | F11: 1902.725 | G11: 1994.9875 | H11: 2035.825 | I11: 2185.5625 | J11: 2389.75 | K11: 2925.175 | L11: 3179.275 | M11: 3332.0375
A12: Труба L=250 мм | B12: 1241.7625 | C12: 1294.7 | D12: 1353.6875 | E12: 1393.0125 | F12: 1506.45 | G12: 1692.4875 | H12: 1719.7125 | I12: 1822.5625 | J12: 2049.4375 | K12: 2357.9875 | L12: 2544.025 | M12: 2654.4375
A13: Труба L=150 мм | B13: 1040.6 | C13: 1099.5875 | D13: 1134.375 | E13: 1160.0875 | F13: 1228.15 | G13: 1279.575 | H13: 1296.2125 | I13: 1359.7375 | J13: 1504.9375 | K13: 1692.4875 | L13: 1805.925 | M13: 1872.475
A14: Отвод 90 гр | B14: 2870.725 | C14: 3037.1 | D14: 3204.9875 | E14: 3383.4625 | F14: 3440.9375 | G14: 3610.3375 | H14: 3914.35 | I14: 4368.1 | J14: 5144.0125 | K14: 6304.1 | L14: 6999.85 | M14: 7462.675
A15: Отвод 45 гр | B15: 2643.85 | C15: 2810.225 | D15: 2978.1125 | E15: 3156.5875 | F15: 3214.0625 | G15: 3383.4625 | H15: 3687.475 | I15: 4141.225 | J15: 4917.1375 | K15: 6077.225 | L15: 6772.975 | M15: 7235.8
A16: Тройник с К/О 90гр | B16: 4369.6125 | C16: 4540.525 | D16: 4800.675 | E16: 4948.9 | F16: 5157.625 | G16: 5514.575 | H16: 5835.225 | I16: 6512.825 | J16: 6959.0125 | K16: 8592.5125 | L16: 9572.6125 | M16: 10226.013
A17: Тройник с К/О 45гр | B17: 5307.3625 | C17: 5454.075 | D17: 5688.5125 | E17: 6205.7875 | F17: 6400.9 | G17: 7102.7 | H17: 7685.0125 | I17: 8361.1 | J17: 9760.1625 | K17: 11432.987 | L17: 12437.288 | M17: 13039.263
A18: Четверник с К/О 90гр | B18: 9856.9625 | C18: 10164 | D18: 10422.638 | E18: 10711.525 | F18: 11038.225 | G18: 11777.837 | H18: 12171.087 | I18: 13016.575 | J18: 14598.65 | K18: 17213.763 | L18: 18783.737 | M18: 11570.625
A19: Заглушка опорная | B19: 1194.875 | C19: 1219.075 | D19: 1306.8 | E19: 1448.975 | F19: 1556.3625 | G19: 1650.1375 | H19: 1792.3125 | I19: 1851.3 | J19: 2069.1 | K19: 2368.575 | L19: 2547.05 | M19: 2652.925
... A22: Зонт-конус | B22: 1769.625 | C22: 1830.125 | D22: 2044.9 | E22: 2096.325 | F22: 2238.5 | G22: 2580.325 | H22: 2708.8875 | I22: 2975.0875 | J22: 3189.8625 | K22: 3882.5875 | L22: 4298.525 | M22: 4548.0875
A24: Розничный прайс-лист на продукцию ООО "Дымоход - Трейд плюс " от 20.01.2025
K25: 50мм
A27: Внутренняя труба — ОЦИНКОВКА
A28: Наружный кожух — Нержавеющая сталь AISI 430 (толщина 0,5мм)
A29: Изоляция — Каолиновая вата (толщина 50мм)
B30: Ø 100/200 | C30: Ø 110/210 | D30: Ø 120/220 | E30: Ø 130/230 | F30: Ø 140/240 | G30: Ø 150/250 | H30: Ø 160/260 | I30: Ø 180/280 | J30: Ø 200/300 | K30: Ø 250/350 | L30: Ø 280/380 | M30: Ø 300/400
A31: Труба L=1000мм | B31: 3268.4437 | C31: 3323.7875 | D31: 3560.975 | E31: 3850.3438 | F31: 4150.7812 | G31: 4329.4625 | H31: 4539.7688 | I31: 4980.9375 | J31: 5455.3125 | K31: 6641.25 | L31: 7352.8125 | M31: 7827.1875
A32: Труба L=750 мм | B32: 2678.6375 | C32: 2882.6188 | D32: 3129.2937 | E32: 3347.5062 | F32: 3546.7438 | G32: 3717.5188 | H32: 3929.4062 | I32: 4489.1687 | J32: 4620.4125 | K32: 5692.5 | L32: 6190.5938 | M32: 6551.1187
A33: Труба L=500 мм | B33: 2087.25 | C33: 2262.7688 | D33: 2466.75 | E33: 2651.7562 | F33: 2903.175 | G33: 3083.4375 | H33: 3205.1937 | I33: 3481.9125 | J33: 3795 | K33: 4625.1562 | L33: 5123.25 | M33: 5455.3125
A34: Труба L=350 мм | B34: 1733.05 | C34: 1891.175 | D34: 2068.275 | E34: 2234.3063 | F34: 2408.2438 | G34: 2490.4688 | H34: 2618.55 | I34: 2805.1375 | J34: 3083.4375 | K34: 3714.3562 | L34: 4092.275 | M34: 4345.275
A35: Труба L=250 мм | B35: 1644.5 | C35: 1663.475 | D35: 1734.6312 | E35: 1786.8125 | F35: 1919.6375 | G35: 2012.9313 | H35: 2052.4625 | I35: 2185.2875 | J35: 2474.6562 | K35: 2849.4125 | L35: 3072.3688 | M35: 3222.5875
A36: Труба L=150 мм | B36: 1253.9313 | C36: 1265 | D36: 1307.6937 | E36: 1337.7375 | F36: 1415.2188 | G36: 1480.05 | H36: 1503.7687 | I36: 1687.1937 | J36: 1869.0375 | K36: 2099.9 | L36: 2237.4688 | M36: 2329.1813
A37: Отвод 90 гр | B37: 3698.5437 | C37: 3998.9812 | D37: 4182.4062 | E37: 4615.6687 | F37: 4917.6875 | G37: 5227.6125 | H37: 5524.8875 | I37: 6195.3375 | J37: 6881.6 | K37: 8628.8813 | L37: 9511.2188 | M37: 9965.0375
A38: Отвод 45 гр | B38: 3461.3562 | C38: 3761.7937 | D38: 3945.2188 | E38: 4378.4812 | F38: 4595.1125 | G38: 4990.425 | H38: 5287.7 | I38: 5958.15 | J38: 6644.4125 | K38: 8391.6938 | L38: 9274.0312 | M38: 9727.85
A39: Тройник с К/О 90гр | B39: 4731.1 | C39: 5050.5125 | D39: 5461.6375 | E39: 5762.075 | F39: 5833.2312 | G39: 6226.9625 | H39: 6576.4187 | I39: 7355.975 | J39: 7944.2 | K39: 9756.3125 | L39: 10842.631 | M39: 11568.425
A40: Тройник с К/О 45гр | B40: 5996.1 | C40: 6302.8625 | D40: 6585.9062 | E40: 7055.5375 | F40: 7423.9688 | G40: 8233.5688 | H40: 9128.5562 | I40: 10055.169 | J40: 11530.475 | K40: 13617.725 | L40: 14870.075 | M40: 15622.75
A41: Четверник с К/О 90гр | B41: 10847.375 | C41: 11212.644 | D41: 11525.731 | E41: 11872.025 | F41: 12259.431 | G41: 13111.725 | H41: 13571.869 | I41: 14563.312 | J41: 16369.1 | K41: 19471.513 | L41: 21334.225 | M41: 22629.269
A42: Заглушка опорная | B42: 1388.3375 | C42: 1416.8 | D42: 1518 | E42: 1682.45 | F42: 1807.3688 | G42: 1918.0563 | H42: 2082.5062 | I42: 2150.5 | J42: 2403.5 | K42: 2749.7937 | L42: 2956.9375 | M42: 3083.4375
... A46: Дефлектор-конус | B46: 2624.875 | C46: 2694.45 | D46: 2912.6625 | E46: 3162.5 | F46: 3352.25 | G46: 3595.7625 | H46: 3848.7625 | I46: 4236.1687 | J46: 4667.85 | K46: 4996.75 | L46: 5042.6062 | M46: 5203.75
A48: Розничный прайс-лист на продукцию ООО "Дымоход - Трейд плюс " от 20.01.2025
K49: 50мм
...

Sheet 25 изол (каолин)
A1: Розничный прайс-лист на продукцию ООО "Дымоход - Трейд плюс " от 20.01.2025
K2: 25мм
A4: Внутренняя труба — ОЦИНКОВКА
A5: Наружный кожух — ОЦИНКОВКА
A6: Изоляция — Каолиновая вата (толщина 25мм)
B7: Ø 100/150 | C7: Ø 110/160 | D7: Ø 120/170 | E7: Ø 130/180 | F7: Ø 140/190 | G7: Ø 150/200 | H7: Ø 160/210 | I7: Ø 180/230 | J7: Ø 200/250 | K7: Ø 250/300 | L7: Ø 280/330 | M7: Ø 300/350
A8: Труба L=1000мм | B8: ='50 изол (каолин)'!B8*0.9 -> 2246.0625 | C8: ='50 изол (каолин)'!C8*0.9 -> 2363.13 | D8: ='50 изол (каолин)'!D8*0.9 -> 2593.1813 | E8: ='50 изол (каолин)'!E8*0.9 -> 2697.9975 | F8: ='50 изол (каолин)'!F8*0.9 -> 2960.7188 | G8: ='50 изол (каолин)'!G8*0.9 -> 3168.99 | H8: ='50 изол (каолин)'!H8*0.9 -> 3369.0938 | I8: ='50 изол (каолин)'!I8*0.9 -> 3625.0087 | ... M8: ='50 изол (каолин)'!M8*0.9 -> 5523.9525
A9: Труба L=750 мм | B9: ='50 изол (каолин)'!B9*0.9 -> 1916.64 | C9: ='50 изол (каолин)'!C9*0.9 -> 2041.875 | D9: ='50 изол (каолин)'!D9*0.9 -> 2191.6125 | E9: ='50 изол (каолин)'!E9*0.9 -> 2371.2975 | F9: ='50 изол (каолин)'!F9*0.9 -> 2533.2863 | G9: ='50 изол (каолин)'!G9*0.9 -> 2661.2438 | H9: ='50 изол (каолин)'!H9*0.9 -> 2733.39 | I9: ='50 изол (каолин)'!I9*0.9 -> 2918.52 | ... M9: ='50 изол (каолин)'!M9*0.9 -> 4360.0837
A10: Труба L=500 мм | B10: ='50 изол (каолин)'!B10*0.9 -> 1570.8825 | C10: ='50 изол (каолин)'!C10*0.9 -> 1677.06 | D10: ='50 изол (каолин)'!D10*0.9 -> 1787.3212 | E10: ='50 изол (каолин)'!E10*0.9 -> 1942.5038 | F10: ='50 изол (каолин)'!F10*0.9 -> 2050.0425 | G10: ='50 изол (каолин)'!G10*0.9 -> 2244.7013 | H10: ='50 изол (каолин)'!H10*0.9 -> 2293.7063 | I10: ='50 изол (каолин)'!I10*0.9 -> 2416.2188 | ... M10: ='50 изол (каолин)'!M10*0.9 -> 3397.68
A11: Труба L=350 мм | B11: ='50 изол (каолин)'!B11*0.9 -> 1302.7162 | C11: ='50 изол (каолин)'!C11*0.9 -> 1437.48 | D11: ='50 изол (каолин)'!D11*0.9 -> 1516.4325 | E11: ='50 изол (каолин)'!E11*0.9 -> 1566.7987 | F11: ='50 изол (каолин)'!F11*0.9 -> 1712.4525 | G11: ='50 изол (каолин)'!G11*0.9 -> 1795.4887 | H11: ='50 изол (каолин)'!H11*0.9 -> 1832.2425 | I11: ='50 изол (каолин)'!I11*0.9 -> 1967.0062 | ... M11: ='50 изол (каолин)'!M11*0.9 -> 2998.8337
A12: Труба L=250 мм | B12: ='50 изол (каолин)'!B12*0.9 -> 1117.5863 | C12: ='50 изол (каолин)'!C12*0.9 -> 1165.23 | D12: ='50 изол (каолин)'!D12*0.9 -> 1218.3187 | E12: ='50 изол (каолин)'!E12*0.9 -> 1253.7113 | F12: ='50 изол (каолин)'!F12*0.9 -> 1355.805 | G12: ='50 изол (каолин)'!G12*0.9 -> 1523.2387 | H12: ='50 изол (каолин)'!H12*0.9 -> 1547.7413 | I12: ='50 изол (каолин)'!I12*0.9 -> 1640.3063 | ... M12: ='50 изол (каолин)'!M12*0.9 -> 2388.9938
A13: Труба L=150 мм | B13: ='50 изол (каолин)'!B13*0.9 -> 936.54 | C13: ='50 изол (каолин)'!C13*0.9 -> 989.62875 | D13: ='50 изол (каолин)'!D13*0.9 -> 1020.9375 | E13: ='50 изол (каолин)'!E13*0.9 -> 1044.0787 | F13: ='50 изол (каолин)'!F13*0.9 -> 1105.335 | G13: ='50 изол (каолин)'!G13*0.9 -> 1151.6175 | H13: ='50 изол (каолин)'!H13*0.9 -> 1166.5912 | I13: ='50 изол (каолин)'!I13*0.9 -> 1223.7638 | ... M13: ='50 изол (каолин)'!M13*0.9 -> 1685.2275
A14: Отвод 90 гр | B14: ='50 изол (каолин)'!B14*0.9 -> 2583.6525 | C14: ='50 изол (каолин)'!C14*0.9 -> 2733.39 | D14: ='50 изол (каолин)'!D14*0.9 -> 2884.4887 | E14: ='50 изол (каолин)'!E14*0.9 -> 3045.1163 | F14: ='50 изол (каолин)'!F14*0.9 -> 3096.8438 | G14: ='50 изол (каолин)'!G14*0.9 -> 3249.3038 | H14: ='50 изол (каолин)'!H14*0.9 -> 3522.915 | I14: ='50 изол (каолин)'!I14*0.9 -> 3931.29 | ... M14: ='50 изол (каолин)'!M14*0.9 -> 6716.4075
A15: Отвод 45 гр | B15: ='50 изол (каолин)'!B15*0.9 -> 2379.465 | C15: ='50 изол (каолин)'!C15*0.9 -> 2529.2025 | D15: ='50 изол (каолин)'!D15*0.9 -> 2680.3012 | E15: ='50 изол (каолин)'!E15*0.9 -> 2840.9288 | F15: ='50 изол (каолин)'!F15*0.9 -> 2892.6562 | G15: ='50 изол (каолин)'!G15*0.9 -> 3045.1163 | H15: ='50 изол (каолин)'!H15*0.9 -> 3318.7275 | I15: ='50 изол (каолин)'!I15*0.9 -> 3727.1025 | ... M15: ='50 изол (каолин)'!M15*0.9 -> 6512.22
A16: Тройник с К/О 90гр | B16: ='50 изол (каолин)'!B16*0.9 -> 3932.6512 | C16: ='50 изол (каолин)'!C16*0.9 -> 4086.4725 | D16: ='50 изол (каолин)'!D16*0.9 -> 4320.6075 | E16: ='50 изол (каолин)'!E16*0.9 -> 4454.01 | F16: ='50 изол (каолин)'!F16*0.9 -> 4641.8625 | G16: ='50 изол (каолин)'!G16*0.9 -> 4963.1175 | H16: ='50 изол (каолин)'!H16*0.9 -> 5251.7025 | I16: ='50 изол (каолин)'!I16*0.9 -> 5861.5425 | ... M16: ='50 изол (каолин)'!M16*0.9 -> 9203.4112
A17: Тройник с К/О 45гр | B17: ='50 изол (каолин)'!B17*0.9 -> 4776.6263 | C17: ='50 изол (каолин)'!C17*0.9 -> 4908.6675 | D17: ='50 изол (каолин)'!D17*0.9 -> 5119.6613 | E17: ='50 изол (каолин)'!E17*0.9 -> 5585.2087 | F17: ='50 изол (каолин)'!F17*0.9 -> 5760.81 | G17: ='50 изол (каолин)'!G17*0.9 -> 6392.43 | H17: ='50 изол (каолин)'!H17*0.9 -> 6916.5112 | I17: ='50 изол (каолин)'!I17*0.9 -> 7524.99 | ... M17: ='50 изол (каолин)'!M17*0.9 -> 11735.336
A18: Четверник с К/О 90гр | B18: ='50 изол (каолин)'!B18*0.9 -> 8871.2663 | C18: ='50 изол (каолин)'!C18*0.9 -> 9147.6 | D18: ='50 изол (каолин)'!D18*0.9 -> 9380.3738 | E18: ='50 изол (каолин)'!E18*0.9 -> 9640.3725 | F18: ='50 изол (каолин)'!F18*0.9 -> 9934.4025 | G18: ='50 изол (каолин)'!G18*0.9 -> 10600.054 | H18: ='50 изол (каолин)'!H18*0.9 -> 10953.979 | I18: ='50 изол (каолин)'!I18*0.9 -> 11714.917 | ... M18: ='50 изол (каолин)'!M18*0.9 -> 10413.562
A19: Заглушка опорная | B19: ='50 изол (каолин)'!B19*0.9 -> 1075.3875 | C19: ='50 изол (каолин)'!C19*0.9 -> 1097.1675 | D19: ='50 изол (каолин)'!D19*0.9 -> 1176.12 | E19: ='50 изол (каолин)'!E19*0.9 -> 1304.0775 | F19: ='50 изол (каолин)'!F19*0.9 -> 1400.7262 | G19: ='50 изол (каолин)'!G19*0.9 -> 1485.1237 | H19: ='50 изол (каолин)'!H19*0.9 -> 1613.0812 | I19: ='50 изол (каолин)'!I19*0.9 -> 1666.17 | ... M19: ='50 изол (каолин)'!M19*0.9 -> 2387.6325
... A22: Зонт-конус | B22: ='50 изол (каолин)'!B22*0.9 -> 1592.6625 | C22: ='50 изол (каолин)'!C22*0.9 -> 1647.1125 | D22: ='50 изол (каолин)'!D22*0.9 -> 1840.41 | E22: ='50 изол (каолин)'!E22*0.9 -> 1886.6925 | F22: ='50 изол (каолин)'!F22*0.9 -> 2014.65 | G22: ='50 изол (каолин)'!G22*0.9 -> 2322.2925 | H22: ='50 изол (каолин)'!H22*0.9 -> 2437.9988 | I22: ='50 изол (каолин)'!I22*0.9 -> 2677.5788 | ... M22: ='50 изол (каолин)'!M22*0.9 -> 4093.2787
A24: Розничный прайс-лист на продукцию ООО "Дымоход - Трейд плюс " от 20.01.2025
K25: 25мм
A27: Внутренняя труба — Оцинковка
A28: Наружный кожух — Нержавеющая сталь AISI 430 (толщина 0,5мм)
A29: Изоляция — Каолиновая вата (толщина 25мм)
B30: Ø 100/150 | C30: Ø 110/160 | D30: Ø 120/170 | E30: Ø 130/180 | F30: Ø 140/190 | G30: Ø 150/200 | H30: Ø 160/210 | I30: Ø 180/230 | J30: Ø 200/250 | K30: Ø 250/300 | L30: Ø 280/330 | M30: Ø 300/350
A31: Труба L=1000мм | B31: ='50 изол (каолин)'!B31*0.9 -> 2941.5994 | C31: ='50 изол (каолин)'!C31*0.9 -> 2991.4088 | D31: ='50 изол (каолин)'!D31*0.9 -> 3204.8775 | E31: ='50 изол (каолин)'!E31*0.9 -> 3465.3094 | F31: ='50 изол (каолин)'!F31*0.9 -> 3735.7031 | G31: ='50 изол (каолин)'!G31*0.9 -> 3896.5163 | H31: ='50 изол (каолин)'!H31*0.9 -> 4085.7919 | I31: ='50 изол (каолин)'!I31*0.9 -> 4482.8438 | ... M31: ='50 изол (каолин)'!M31*0.9 -> 7044.4688
A32: Труба L=750 мм | B32: ='50 изол (каолин)'!B32*0.9 -> 2410.7737 | C32: ='50 изол (каолин)'!C32*0.9 -> 2594.3569 | D32: ='50 изол (каолин)'!D32*0.9 -> 2816.3644 | E32: ='50 изол (каолин)'!E32*0.9 -> 3012.7556 | F32: ='50 изол (каолин)'!F32*0.9 -> 3192.0694 | G32: ='50 изол (каолин)'!G32*0.9 -> 3345.7669 | H32: ='50 изол (каолин)'!H32*0.9 -> 3536.4656 | I32: ='50 изол (каолин)'!I32*0.9 -> 4040.2519 | ... M32: ='50 изол (каолин)'!M32*0.9 -> 5896.0069
A33: Труба L=500 мм | B33: ='50 изол (каолин)'!B33*0.9 -> 1878.525 | C33: ='50 изол (каолин)'!C33*0.9 -> 2036.4919 | D33: ='50 изол (каолин)'!D33*0.9 -> 2220.075 | E33: ='50 изол (каолин)'!E33*0.9 -> 2386.5806 | F33: ='50 изол (каолин)'!F33*0.9 -> 2612.8575 | G33: ='50 изол (каолин)'!G33*0.9 -> 2775.0938 | H33: ='50 изол (каолин)'!H33*0.9 -> 2884.6744 | I33: ='50 изол (каолин)'!I33*0.9 -> 3133.7213 | ... M33: ='50 изол (каолин)'!M33*0.9 -> 4909.7812
A34: Труба L=350 мм | B34: ='50 изол (каолин)'!B34*0.9 -> 1559.745 | C34: ='50 изол (каолин)'!C34*0.9 -> 1702.0575 | D34: ='50 изол (каолин)'!D34*0.9 -> 1861.4475 | E34: ='50 изол (каолин)'!E34*0.9 -> 2010.8756 | F34: ='50 изол (каолин)'!F34*0.9 -> 2167.4194 | G34: ='50 изол (каолин)'!G34*0.9 -> 2241.4219 | H34: ='50 изол (каолин)'!H34*0.9 -> 2356.695 | I34: ='50 изол (каолин)'!I34*0.9 -> 2524.6238 | ... M34: ='50 изол (каолин)'!M34*0.9 -> 3910.7475
A35: Труба L=250 мм | B35: ='50 изол (каолин)'!B35*0.9 -> 1480.05 | C35: ='50 изол (каолин)'!C35*0.9 -> 1497.1275 | D35: ='50 изол (каолин)'!D35*0.9 -> 1561.1681 | E35: ='50 изол (каолин)'!E35*0.9 -> 1608.1312 | F35: ='50 изол (каолин)'!F35*0.9 -> 1727.6737 | G35: ='50 изол (каолин)'!G35*0.9 -> 1811.6381 | H35: ='50 изол (каолин)'!H35*0.9 -> 1847.2162 | I35: ='50 изол (каолин)'!I35*0.9 -> 1966.7587 | ... M35: ='50 изол (каолин)'!M35*0.9 -> 2900.3288
A36: Труба L=150 мм | B36: ='50 изол (каолин)'!B36*0.9 -> 1128.5381 | C36: ='50 изол (каолин)'!C36*0.9 -> 1138.5 | D36: ='50 изол (каолин)'!D36*0.9 -> 1176.9244 | E36: ='50 изол (каолин)'!E36*0.9 -> 1203.9637 | F36: ='50 изол (каолин)'!F36*0.9 -> 1273.6969 | G36: ='50 изол (каолин)'!G36*0.9 -> 1332.045 | H36: ='50 изол (каолин)'!H36*0.9 -> 1353.3919 | I36: ='50 изол (каолин)'!I36*0.9 -> 1518.4744 | ... M36: ='50 изол (каолин)'!M36*0.9 -> 2096.2631
A37: Отвод 90 гр | B37: ='50 изол (каолин)'!B37*0.9 -> 3328.6894 | C37: ='50 изол (каолин)'!C37*0.9 -> 3599.0831 | D37: ='50 изол (каолин)'!D37*0.9 -> 3764.1656 | E37: ='50 изол (каолин)'!E37*0.9 -> 4154.1019 | F37: ='50 изол (каолин)'!F37*0.9 -> 4425.9187 | G37: ='50 изол (каолин)'!G37*0.9 -> 4704.8512 | H37: ='50 изол (каолин)'!H37*0.9 -> 4972.3988 | I37: ='50 изол (каолин)'!I37*0.9 -> 5575.8038 | ... M37: ='50 изол (каолин)'!M37*0.9 -> 8968.5338
A38: Отвод 45 гр | B38: ='50 изол (каолин)'!B38*0.9 -> 3115.2206 | C38: ='50 изол (каолин)'!C38*0.9 -> 3385.6144 | D38: ='50 изол (каолин)'!D38*0.9 -> 3550.6969 | E38: ='50 изол (каолин)'!E38*0.9 -> 3940.6331 | F38: ='50 изол (каолин)'!F38*0.9 -> 4135.6012 | G38: ='50 изол (каолин)'!G38*0.9 -> 4491.3825 | H38: ='50 изол (каолин)'!H38*0.9 -> 4758.93 | I38: ='50 изол (каолин)'!I38*0.9 -> 5362.335 | ... M38: ='50 изол (каолин)'!M38*0.9 -> 8755.065
A39: Тройник с К/О 90гр | B39: ='50 изол (каолин)'!B39*0.9 -> 4257.99 | C39: ='50 изол (каолин)'!C39*0.9 -> 4545.4613 | D39: ='50 изол (каолин)'!D39*0.9 -> 4915.4738 | E39: ='50 изол (каолин)'!E39*0.9 -> 5185.8675 | F39: ='50 изол (каолин)'!F39*0.9 -> 5249.9081 | G39: ='50 изол (каолин)'!G39*0.9 -> 5604.2662 | H39: ='50 изол (каолин)'!H39*0.9 -> 5918.7769 | I39: ='50 изол (каолин)'!I39*0.9 -> 6620.3775 | ... M39: ='50 изол (каолин)'!M39*0.9 -> 10411.583
A40: Тройник с К/О 45гр | B40: ='50 изол (каолин)'!B40*0.9 -> 5396.49 | C40: ='50 изол (каолин)'!C40*0.9 -> 5672.5763 | D40: ='50 изол (каолин)'!D40*0.9 -> 5927.3156 | E40: ='50 изол (каолин)'!E40*0.9 -> 6349.9838 | F40: ='50 изол (каолин)'!F40*0.9 -> 6681.5719 | G40: ='50 изол (каолин)'!G40*0.9 -> 7410.2119 | H40: ='50 изол (каолин)'!H40*0.9 -> 8215.7006 | I40: ='50 изол (каолин)'!I40*0.9 -> 9049.6519 | ... M40: ='50 изол (каолин)'!M40*0.9 -> 14060.475
A41: Четверник с К/О 90гр | B41: ='50 изол (каолин)'!B41*0.9 -> 9762.6375 | C41: ='50 изол (каолин)'!C41*0.9 -> 10091.379 | D41: ='50 изол (каолин)'!D41*0.9 -> 10373.158 | E41: ='50 изол (каолин)'!E41*0.9 -> 10684.823 | F41: ='50 изол (каолин)'!F41*0.9 -> 11033.488 | G41: ='50 изол (каолин)'!G41*0.9 -> 11800.552 | H41: ='50 изол (каолин)'!H41*0.9 -> 12214.682 | I41: ='50 изол (каолин)'!I41*0.9 -> 13106.981 | ... M41: ='50 изол (каолин)'!M41*0.9 -> 20366.342
A42: Заглушка опорная | B42: ='50 изол (каолин)'!B42*0.9 -> 1249.5038 | C42: ='50 изол (каолин)'!C42*0.9 -> 1275.12 | D42: ='50 изол (каолин)'!D42*0.9 -> 1366.2 | E42: ='50 изол (каолин)'!E42*0.9 -> 1514.205 | F42: ='50 изол (каолин)'!F42*0.9 -> 1626.6319 | G42: ='50 изол (каолин)'!G42*0.9 -> 1726.2506 | H42: ='50 изол (каолин)'!H42*0.9 -> 1874.2556 | I42: ='50 изол (каолин)'!I42*0.9 -> 1935.45 | ... M42: ='50 изол (каолин)'!M42*0.9 -> 2775.0938
... A46: Дефлектор-конус | B46: ='50 изол (каолин)'!B46*0.9 -> 2362.3875 | C46: ='50 изол (каолин)'!C46*0.9 -> 2425.005 | D46: ='50 изол (каолин)'!D46*0.9 -> 2621.3962 | E46: ='50 изол (каолин)'!E46*0.9 -> 2846.25 | F46: ='50 изол (каолин)'!F46*0.9 -> 3017.025 | G46: ='50 изол (каолин)'!G46*0.9 -> 3236.1863 | H46: ='50 изол (каолин)'!H46*0.9 -> 3463.8863 | I46: ='50 изол (каолин)'!I46*0.9 -> 3812.5519 | ... M46: ='50 изол (каолин)'!M46*0.9 -> 4683.375
A48: Розничный прайс-лист на продукцию ООО "Дымоход - Трейд плюс " от 20.01.2025
K49: 25мм
...

Sheet Фланцы
A1: Розничный прайс-лист на продукцию ООО "Дымоход - Трейд плюс " от 01.01.2024
A3: Проходной узел кровли | C3: 500*500 | D3: 600*600 | E3: 800*800 | F3: 1000*800 | I3: 1000*1000
C4: 100-125 | D4: 130-155 | E4: 160-185 | F4: 190-210 | G4: 215-245 | H4: 250-275 | I4: 280-300 | J4: 305-350 | K4: 350-400
A5: Оцинковка | C5: 2805 | D5: 3003 | E5: 3465 | F5: 4433 | G5: 4675 | H5: 4950 | I5: 5060 | J5: 5577 | K5: 6050
A6: Нерж 304 | C6: 4372.5 | D6: 5115 | E6: 6270 | F6: 8030 | G6: 9350 | H6: 9570 | I6: 10560 | J6: 11385 | K6: 12210
A7: Нерж 430 | C7: 3465 | D7: 4015 | E7: 4730 | F7: 6050 | G7: 6710 | H7: 7040 | I7: 7920 | J7: 8690 | K7: 9350
A9: Проходной стакан
C10: 500*500 гильза Д400 | F10: 600*600 гильза Д400 | I10: 700*700 гильза Д450
C11: Ø 100-200 | F11: Ø 210-280 | I11: Ø 300-400
A12: Оцинковка | C12: 1760 | F12: 2090 | I12: 2475
A13: Нерж 304 | C13: 4125 | F13: 4785 | I13: 5775
A14: Нерж 430 | C14: 2816 | F14: 3950 | I14: 4455
C15: Комплект Ваты в стакан 1000 руб
A17: Фланец Декоративный
C18: 500*500 | D18: 500*650 | E18: 600*600 | F18: 650*650 | G18: 600*750 | H18: 700*700 | I18: 750*750 | J18: 800*800 | K18: 800*850 | L18: 800*1000 | M18: 1000*1000
A19: Оцинковка | C19: 605 | D19: 715 | E19: 770 | F19: 825 | G19: 880 | H19: 935 | I19: 990 | J19: 1100 | K19: 1210 | L19: 1375 | M19: 1650
A20: Оцинковка под углом | C20: 726 | D20: 858 | E20: 924 | F20: 990 | G20: 1056 | H20: 1122 | I20: 1188 | J20: 1320 | K20: 1452 | L20: 1650 | M20: 1980
A21: Нерж 304 | C21: 1881 | D21: 2090 | E21: 2299 | F21: 2466.2 | G21: 2508 | H21: 2717 | I21: 2926 | J21: 3239.5 | K21: 3344 | L21: 3866.5 | M21: 4702.5
A22: Нерж 304 под углом | C22: 2257.2 | D22: 2508 | E22: 2758.8 | F22: 2959 | G22: 3009.6 | H22: 3260.4 | I22: 3511.2 | J22: 3887.4 | K22: 4012.8 | L22: 4639.8 | M22: 5643
A23: Нерж 430 | C23: 1133 | D23: 1496 | E23: 1672 | F23: 1760 | G23: 1870 | H23: 1925 | I23: 1980 | J23: 2035 | K23: 2090 | L23: 2310 | M23: 2475
A24: Нерж 430 под углом | C24: 1359.6 | D24: 1795.2 | E24: 2006.4 | F24: 2112 | G24: 2244 | H24: 2310 | I24: 2376 | J24: 2442 | K24: 2508 | L24: 2772 | M24: 2970
A26: Лист | C26: 500*500 | D26: 600*600 | E26: 700*700 | F26: 800*800 | G26: 900*900 | H26: 1000*1000 | I26: 1000*1500 | J26: 1000*2000
A27: Оцинковка | C27: По фланцу | H27: 1210 | I27: 1760 | J27: 2200
A28: Нерж 304 | H28: 4510 | I28: 6490 | J28: 8580
A29: Нерж 430 | H29: 2200 | I29: 3080 | J29: 3960
A31: Розничный прайс-лист на продукцию ООО "Дымоход - Трейд плюс " от 01.01.2024
A33: Консоль универсальная | D33: Консоль табурет | H33: Консоль телескопическая | K33: Хомут в перекрытие/силовой
A34: до 930мм до Д350 | B34: 3000 | D34: 400-850мм | E34: =4500*1.1 -> 4950 | H34: до 930мм | I34: =1800*1.1 -> 1980 | K34: до Д300 | L34: =1600*1.1 -> 1760
A35: до 1200/Д500 | B35: 4000 | D35: 900-2000 | E35: =5500*1.1 -> 6050 | H35: 900-1200 | I35: 2500 | K35: от Д300 | L35: =2000*1.1 -> 2200
A37: Минерит | C37: Фаспан АНТИФЛЕЙМ | G37: Везувий Фаспан | K37: РАСПОРКИ по 1000р
A38: 1200*630*9 | C38: 1200*600*9 | D38: 1200*800*9 | E38: 1200*1200*9 | G38: 1200*600*8 | H38: 1200*800*8 | I38: 1200*1200*8
A39: 4440 | C39: 2220 | D39: 2960 | E39: 4430 | G39: 1950 | H39: 2750 | I39: 3900
A41: Grillux Лист притопочный
A42: 1000* 800 | B42: бронза медь черный | C42: R641 | E42: 1000* 1000 | F42: бронза медь черный | G42: R641 | I42: 1200* 1200 | J42: бронза медь черный | L42: Радиальный 900* 800 | M42: бронза медь черный
B43: 3930 | C43: 3840 | F43: 5730 | G43: 5320 | J43: 8110 | M43: 3110
A45: R641 | C45: обычный | F45: Grillux Лист угловой-призматический | K45: Grillux Лист угловой
H46: 1100*1100 | L46: 1095*700
H47: Черный | I47: 5350 | L47: Черный | M47: 3540
H48: медь | L48: медь
H49: Бронза | L49: Бронза
...

Sheet комплекты
A1: КОМПЛЕКТЫ ЭКОНОМ
A2: Комплект Эконом №1 | C2: Д115/215 | D2: Д120/220 | E2: Д150/250 | G2: =G9+G8+G7*2+G6*3+G5+G4+G3 -> 20524.415 | H2: =H9+H8+H7*2+H6*3+H5+H4+H3 -> 24171.19
A3: Труба 1000мм нерж 304(0.8) | B3: 1 шт | C3: =G2*0.9 -> 18471.974 | D3: =C3 -> 18471.974 | E3: =H2*0.9 -> 21754.071 | G3: =голые!D96 -> 1992.375 | H3: =голые!G96 -> 2493.315
A4: Шибер поворотный нерж 304(0.8) | B4: 1 шт | G4: =голые!D107 -> 2120.14 | H4: =голые!G107 -> 2338.985
A5: Заглушка опорная нерж 304(0.5)/Оц | B5: 1 шт | G5: ='50 изоляция'!D159 -> 1306.8 | H5: ='50 изоляция'!G159 -> 1650.44
A6: Сэндвич 1000мм нерж 304(0.5)/ОЦ | B6: 3 шт | G6: ='50 изоляция'!D148 -> 3073.4 | H6: ='50 изоляция'!G148 -> 3755.84
A7: Фланцы 600*600 Оц | B7: 2 шт | G7: =Фланцы!E19 -> 770 | H7: =G7 -> 770
A8: Мастер флеш №2 | B8: 1 шт | G8: 2300 | H8: =G8 -> 2300
A9: Зонт-конус нерж 304(0.5)/ОЦ | B9: 1 шт | G9: ='50 изоляция'!D162 -> 2044.9 | H9: ='50 изоляция'!G162 -> 2580.93
A11: Комплект Эконом №2 | C11: Д115/215 | D11: Д120/220 | E11: Д150/250 | G11: =G21+G20+G19*2+G18*3+G17+G16+G15+G14*2+G13+G12 -> 33815.315 | H11: =H21+H20+H19*2+H18*3+H17+H16+H15+H14*2+H13+H12 -> 39132.055
A12: Шибер выдвижной нерж 304(0.8) | B12: 1 шт | C12: =G11*0.9 -> 30433.784 | D12: =C12 -> 30433.784 | E12: =H11*0.9 -> 35218.849 | G12: =голые!D108 -> 2145.44 | H12: =голые!G108 -> 2433.86
A13: Заглушка опорная нерж 304(0.8)/Оц | B13: 1 шт | G13: ='50 изоляция'!D182 -> 1465.31 | H13: ='50 изоляция'!G182 -> 1844.04
A14: Фланцы 600*600 Оц | B14: 2 шт | G14: =G7 -> 770 | H14: =G14 -> 770
A15: Сэндвич-труба 500мм нерж 304(0.8)/ОЦ | B15: 1 шт | G15: ='50 изоляция'!D171 -> 3651.78 | H15: ='50 изоляция'!G171 -> 4346.32
A16: Тройник с к/о нерж 304(0.5)/ОЦ | B16: 1шт | G16: ='50 изоляция'!D156 -> 4800.07 | H16: ='50 изоляция'!G156 -> 5881.81
A17: Площадка под тройник 304(0.5)430 | B17: 1шт | G17: =Фланцы!D52 -> 2250.6 | H17: =Фланцы!G52 -> 2467.19
A18: Сэндвич 1000мм нерж 304(0.5)/ОЦ | B18: 3шт | G18: ='50 изоляция'!D148 -> 3073.4 | H18: ='50 изоляция'!G148 -> 3755.84
A19: Консоль Универсальная | B19: 2шт | G19: =Фланцы!B34 -> 3000 | H19: =G19 -> 3000
A20: Хомут силовой для консоли 430(0.8) | B20: 1шт | G20: =голые!L45 -> 697.015 | H20: =голые!N45 -> 770.385
A21: Зонт-конус нерж 304(0.5)/ОЦ | B21: 1шт | G21: =G9 -> 2044.9 | H21: =H9 -> 2580.93
A23: Комплект Эконом №3 | C23: Д115/215 | D23: Д120/220 | E23: Д150/250 | G23: =G30+G29+G28*4+G27*6+G26+G25+G24 -> 31284.615 | H23: =H30+H29+H28*4+H27*6+H26+H25+H24 -> 36978.71
A24: Труба 1000мм нерж 304(0.8) | B24: 1шт | C24: =G23*0.9 -> 28156.154 | D24: =C24 -> 28156.154 | E24: =H23*0.9 -> 33280.839 | G24: =G3 -> 1992.375 | H24: =H3 -> 2493.315
A25: Шибер поворотный нерж 304(0.8) | B25: 1шт | G25: =G4 -> 2120.14 | H25: =H4 -> 2338.985
A26: Заглушка опорная нерж 304(0.5)/Оц | B26: 1шт | G26: =G5 -> 1306.8 | H26: =H5 -> 1650.44
A27: Сэндвич 1000мм нерж 304(0.5)/ОЦ | B27: 6шт | G27: =G6 -> 3073.4 | H27: =H6 -> 3755.84
A28: Фланцы 600*600 Оц | B28: 4шт | G28: =G7 -> 770 | H28: =H7 -> 770
A29: Мастер флеш №2 | B29: 1шт | G29: =G8 -> 2300 | H29: =H8 -> 2300
A30: Зонт-конус нерж 304(0.5)/ОЦ | B30: 1шт | G30: =G9 -> 2044.9 | H30: =H9 -> 2580.93
A32: Комплект Эконом №4 | C32: Д115/215 | D32: Д120/220 | E32: Д150/250 | G32: =G33+G34+G35*2+G36+G37+G38+G39*6+G40*3+G41*2+G42 -> 46732.53 | H32: =H33+H34+H35*2+H36+H37+H38+H39*6+H40*3+H41*2+H42 -> 54169.96
A33: Шибер выдвижной нерж 304(0.8) | B33: 1шт | C33: =G32*0.9 -> 42059.277 | D33: =C33 -> 42059.277 | E33: =H32*0.9 -> 48752.964 | G33: =G12 -> 2145.44 | H33: =H12 -> 2433.86
A34: Заглушка опорная нерж 304(0.8)/Оц | B34: 1шт | G34: =G13 -> 1465.31 | H34: =H13 -> 1844.04
A35: Фланцы 600*600 Оц | B35: 2шт | G35: =G14 -> 770 | H35: =H14 -> 770
A36: Сэндвич-труба 500мм нерж 304(0.8)/ОЦ | B36: 1шт | G36: =G15 -> 3651.78 | H36: =H15 -> 4346.32
A37: Тройник с к/о нерж 304(0.5)/ОЦ | B37: 1шт | G37: =G16 -> 4800.07 | H37: =H16 -> 5881.81
A38: Площадка под тройник 304(0.5)430 | B38: 1шт | G38: =G17 -> 2250.6 | H38: =H17 -> 2467.19
A39: Сэндвич 1000мм нерж 304(0.5)/ОЦ | B39: 6шт | G39: =G18 -> 3073.4 | H39: =H18 -> 3755.84
A40: Консоль Универсальная | B40: 3шт | G40: =G19 -> 3000 | H40: =H19 -> 3000
A41: Хомут силовой для консоли 430(0.8) | B41: 2шт | G41: =G20 -> 697.015 | H41: =H20 -> 770.385
A42: Зонт-конус нерж 304(0.5)/ОЦ | B42: 1шт | G42: =G21 -> 2044.9 | H42: =H21 -> 2580.93
G43: =G22 -> 0 | H43: =H22 -> 0
...
